Workbook

Sheet Summary
A4: This Workbook tracks the IT Teams resource usage over the year aswell as providing a comparison with the previous year.
A6: Year 2026 | D6: Jan | E6: Feb | F6: March | G6: April | H6: May | I6: June | J6: July | K6: August | L6: September | M6: October | N6: November | O6: December
B7: MGMT | D7: {='2026'!D52:O52} -> 0.86607143 | E7: 0.565 | F7: 0.66666667 | G7: 0.99473684 | H7: 0.975 | I7: 0.96 | J7: 1 | K7: 0.99047619 | L7: 1 | M7: 1 | N7: 1 | O7: 1 | P7: =AVERAGE(_xlfn.ANCHORARRAY(D7)) -> 0.91816259 | S7: Jan | T7: Feb | U7: March | V7: April | W7: May | X7: June | Y7: July | Z7: August | AA7: September | AB7: October | AC7: November | AD7: December | AE7: Total
B8: Service Desk | D8: {='2026'!D47:O47} -> 0.6952381 | E8: 0.88125 | F8: 0.83333333 | G8: 0.99013158 | H8: 0.975 | I8: 0.99 | J8: 1 | K8: 1 | L8: 1 | M8: 1 | N8: 0.88125 | O8: 1 | P8: =AVERAGE(D8:O8) -> 0.93718358 | R8: Capacity (Full Team) | S8: 2500 | T8: 2300 | U8: 2300 | V8: 2300 | W8: 2300 | X8: 2300 | Y8: 2300 | Z8: 2300 | AA8: 2300 | AB8: 2300 | AC8: 2300 | AD8: 2300 | AE8: =SUM(S8:AD8) -> 27800
B9: OST | D9: {='2026'!D50:O50} -> 0.85714286 | E9: 0.725 | F9: 0.95238095 | G9: 0.97368421 | H9: 0.975 | I9: 1 | J9: 0.89130435 | K9: 1 | L9: 1 | M9: 1 | N9: 1 | O9: 1 | P9: =AVERAGE(D9:O9) -> 0.94787603 | R9: Opened | S9: 1664 | T9: 1520 | AE9: =SUM(S9:AD9) -> 3184
B10: OST BaB | D10: {='2026'!D51:O51} -> 0.84126984 | E10: 0.725 | F10: 0.77777778 | G10: 1 | H10: 1 | I10: 1 | J10: 1 | K10: 1 | L10: 1 | M10: 1 | N10: 1 | O10: 1 | P10: =AVERAGE(D10:O10) -> 0.9453373 | R10: Closed | S10: 1634 | T10: 1530 | AE10: =SUM(S10:AD10) -> 3164
B11: Projects | D11: {='2026'!D52:O52} -> 0.86607143 | E11: 0.565 | F11: 0.66666667 | G11: 0.99473684 | H11: 0.975 | I11: 0.96 | J11: 1 | K11: 0.99047619 | L11: 1 | M11: 1 | N11: 1 | O11: 1 | P11: =AVERAGE(D11:O11) -> 0.91816259 | S11: JM Left
D12: Jan | E12: Feb | F12: March | G12: April | H12: May | I12: June | J12: July | K12: August | L12: September | M12: October | N12: November | O12: December | P12: =AVERAGE(P7:P11) -> 0.93334442 | T12: 1x Support Engineer Vacancy
D13: Q1 | G13: Q2 | J13: Q3 | M13: Q4
B14: <90% >110% | D14: =AVERAGE(D7:F11) -> 0.76559127 | G14: =AVERAGE(G7:I11) -> 0.9842193 | J14: =AVERAGE(J7:L11) -> 0.99148378 | M14: =AVERAGE(M7:O11) -> 0.99208333
A15: Within Capacity | B15: Under resourced | C15: Over Resourced | D15: PM Vacancy - 1x Support Engineer Feb
A37: Year 2025 | D37: Jan | E37: Feb | F37: March | G37: April | H37: May | I37: June | J37: July | K37: August | L37: September | M37: October | N37: November | O37: December
B38: Service Desk | D38: {='2025'!E45:P45} -> 0.90909091 | E38: 0.94375 | F38: 0.78571429 | G38: 0.8625 | H38: 0.8875 | I38: 0.895 | J38: 0.82608696 | K38: 0.81875 | L38: 0.74147727 | M38: 0.75271739 | N38: 0.93125 | O38: 0.7797619 | P38: =AVERAGE(_xlfn.ANCHORARRAY(D38)) -> 0.84446656 | S38: Jan | T38: Feb | U38: March | V38: April | W38: May | X38: June | Y38: July | Z38: August | AA38: September | AB38: October | AC38: November | AD38: December | AE38: Total
B39: OST | D39: {='2025'!E47:P50} -> 1.5454545 | E39: 0.7 | F39: 0.72486772 | G39: 0.825 | H39: 0.825 | I39: 0.8 | J39: 1.1521739 | K39: 1.3 | L39: 1.1590909 | M39: 0.76086957 | N39: 0.75 | O39: 1 | P39: =AVERAGE(D39:O39) -> 0.96187139 | R39: Capacity (Full Team) | S39: 1312 | T39: 1312 | U39: 1312 | V39: 2500 | W39: 2500 | X39: 2500 | Y39: 2500 | Z39: 2500 | AA39: 2500 | AB39: 2500 | AC39: 2500 | AD39: 2500 | AE39: =SUM(S39:AD39) -> 26436
B40: OST BaB | D40: 0.90909091 | E40: 0.925 | F40: 0.76190476 | G40: 0.9 | H40: 0.9 | I40: 0.74 | J40: 0.86956522 | K40: 0.775 | L40: 0.93181818 | M40: 1.1956522 | N40: 1.075 | O40: 0.83333333 | P40: =AVERAGE(D40:O40) -> 0.90136371 | R40: Opened | S40: 1075 | T40: 1040 | U40: 991 | V40: 1795 | W40: 2447 | X40: 3702 | Y40: 3702 | Z40: 2555 | AA40: 2121 | AB40: 2005 | AC40: 2226 | AD40: 1487 | AE40: =SUM(S40:AD40) -> 25146
B41: Projects | D41: 0.96969697 | E41: 0.86666667 | F41: 0.93650794 | G41: 1.1333333 | H41: 1.1333333 | I41: 0.89333333 | J41: 0.88405797 | K41: 0.85 | L41: 0.95454545 | M41: 0.88405797 | N41: 0.96666667 | O41: 0.96825397 | P41: =AVERAGE(D41:O41) -> 0.95337113 | R41: Closed | S41: 910 | T41: 1040 | U41: 1000 | V41: 1773 | W41: 2620 | X41: 3687 | Y41: 3678 | Z41: 2451 | AA41: 2235 | AB41: 2068 | AC41: 2183 | AD41: 1548 | AE41: =SUM(S41:AD41) -> 25193
B42: MGMT | D42: 0.67451299 | E42: 0.8125 | F42: 0.70238095 | G42: 0.6125 | H42: 0.6125 | I42: 0.824 | J42: 0.49565217 | K42: 0.53 | L42: 0.77272727 | M42: 0.67608696 | N42: 0.64 | O42: 0.60952381 | P42: =AVERAGE(D42:O42) -> 0.66353201 | S42: Connectwise - Exc Alerts | V42: *Moved to HALO
D43: Jan | E43: Feb | F43: March | G43: April | H43: May | I43: June | J43: July | K43: August | L43: September | M43: October | N43: November | O43: December | P43: =AVERAGE(P38:P42) -> 0.86492096 | V43: Includes test tickets/duplicates
D44: Q1 | G44: Q2 | J44: Q3 | M44: Q4 | V44: *includes Alerts >
B45: <90% >110% | D45: =AVERAGE(D38:F42) -> 0.87780924 | G45: =AVERAGE(G38:I42) -> 0.85626667 | J45: =AVERAGE(J38:L42) -> 0.87072969 | M45: =AVERAGE(M38:O42) -> 0.85487825
A46: Within Capacity | B46: Under resourced | C46: Over Resourced | D46: Maternity Leave - Jan - Sept, SDM/OPs July - September - PM Vacancy - Oct >
A67: Year 2024
B68: SD Available | D68: 0.45 | E68: 0.45 | F68: 0.59 | G68: 0.82 | H68: ='2024'!$I$47 -> 0.76984127 | I68: ='2024'!$J$47 -> 0.78333333 | J68: ='2024'!$K$47 -> 0.725 | K68: ='2024'!$L$47 -> 0.6462585 | L68: ='2024'!$M$47 -> 0.74829932 | M68: ='2024'!$N$47 -> 0.80745342 | N68: ='2024'!$O$47 -> 0.73214286 | O68: ='2024'!$P$47 -> 0.53125 | P68: =AVERAGE(D68:O68) -> 0.67113156 | S68: Jan | T68: Feb | U68: March | V68: April | W68: May | X68: June | Y68: July | Z68: August | AA68: September | AB68: October | AC68: November | AD68: December | AE68: Total
B69: OST | D69: {='2024'!$E$49:$P$51} -> 1.25 | E69: 1.25 | F69: 1.125 | G69: 0.92857143 | H69: 0.8015873 | I69: 0.8 | J69: 1 | K69: 0.95238095 | L69: 0.64285714 | M69: 1 | N69: 1.3571429 | O69: 1.95 | P69: =AVERAGE(D69:O69) -> 1.0881283 | R69: Capacity Current | S69: 1312 | T69: 1312 | U69: 1312 | V69: 1312 | W69: 1312 | X69: 1312 | Y69: 1312 | Z69: 1312 | AA69: 1312 | AB69: 1312 | AC69: 1312 | AD69: 1312 | AE69: =SUM(S69:AD69) -> 15744
B70: OST BaB | D70: 0.75 | E70: 0.75 | F70: 0.95 | G70: 1 | H70: 0.66666667 | I70: 0.75 | J70: 0.825 | K70: 0.85714286 | L70: 0.9047619 | M70: 0.89130435 | N70: 0.83333333 | O70: 0.8 | P70: =AVERAGE(D70:O70) -> 0.83151743 | R70: Opened | S70: 1587 | T70: 1370 | U70: 1400 | V70: 1256 | W70: 1008 | X70: 1211 | Y70: 1107 | Z70: 912 | AA70: 1290 | AB70: 1114 | AC70: 1030 | AD70: 698 | AE70: =SUM(S70:AD70) -> 13983
B71: Projects | D71: 1.35 | E71: 1.35 | F71: 1.1 | G71: 0.80952381 | H71: 0.8015873 | I71: 0.8125 | J71: 0.6625 | K71: 0.53571429 | L71: 0.73015873 | M71: 0.66666667 | N71: 0.76190476 | O71: 0.71666667 | P71: =AVERAGE(D71:O71) -> 0.85810185 | R71: Closed | S71: 1076 | T71: 900 | U71: 1150 | V71: 1175 | W71: 1111 | X71: 1063 | Y71: 1076 | Z71: 925 | AA71: 1270 | AB71: 1117 | AC71: 1010 | AD71: 711 | AE71: =SUM(S71:AD71) -> 12584
B72: MGMT | D72: {='2024'!$E$52:$P$52} -> 0.5 | E72: 0.5 | F72: 0.9 | G72: 0.89285714 | H72: 0.89285714 | I72: 0.9625 | J72: 0.9625 | K72: 0.80952381 | L72: 0.79761905 | M72: 0.69565217 | N72: 0.88095238 | O72: 0.75 | P72: =AVERAGE(D72:O72) -> 0.79537181
D73: Jan | E73: Feb | F73: March | G73: April | H73: May | I73: June | J73: July | K73: August | L73: September | M73: October | N73: November | O73: December | P73: =AVERAGE(P68:P72) -> 0.84885019
D74: Q1 | G74: Q2 | J74: Q3 | M74: Q4
B75: <90% >110% | D75: 0.88 | G75: =AVERAGE(G68:I72) -> 0.83278836 | J75: =AVERAGE(J68:L72) -> 0.78664777 | M75: =AVERAGE(M68:O72) -> 0.8916313
A76: Within Capacity | B76: Under resourced | C76: Over Resourced | D76: x1 Project Engineer Vacancy 1x 3rd Line Vacancy 1x OST | G76: x1 Project Engineer Vacancy 1x 3rd Line Vacancy | J76: x1 Project Engineer Vacancy 1x 3rd Line Vacancy
B109: Over Resourced | C109: 1.1 | D109: 1.1 | E109: 1.1 | F109: 1.1 | G109: 1.1 | H109: 1.1 | I109: 1.1 | J109: 1.1 | K109: 1.1 | L109: 1.1 | M109: 1.1 | N109: 1.1
B110: Capacity | C110: 1 | D110: 1 | E110: 1 | F110: 1 | G110: 1 | H110: 1 | I110: 1 | J110: 1 | K110: 1 | L110: 1 | M110: 1 | N110: 1
B111: Under Resourced | C111: 0.9 | D111: 0.9 | E111: 0.9 | F111: 0.9 | G111: 0.9 | H111: 0.9 | I111: 0.9 | J111: 0.9 | K111: 0.9 | L111: 0.9 | M111: 0.9 | N111: 0.9

Sheet 2024
A1: Staff Member | B1: Normal Area Of Work | C1: Tier | D1: Monday 26/02/24 | E1: Tuesday 27/02/24 | F1: Wednesday 28/02/24 | G1: Thursday 29/02/24 | H1: Friday 01/03/24 | I1: Saturday 02/03/24 | J1: Sunday 03/03/24 | K1: Monday 04/03/24 | L1: Tuesday 05/03/24 | M1: Wednesday 06/03/24 | N1: Thursday 07/03/24 | O1: Friday 08/03/24 | P1: Saturday 09/03/24 | Q1: Sunday 10/03/24 | R1: Monday 11/03/24 | S1: Tuesday 12/03/24 | T1: Wednesday 13/03/24 | U1: Thursday 14/03/24 | V1: Friday 15/03/24 | W1: Saturday 16/03/24 | X1: Sunday 17/03/24 | Y1: Monday 18/03/24 | Z1: Tuesday 19/03/25 | AA1: Wednesday 20/03/24 | AB1: Thursday 21/03/24 | AC1: Friday 22/03/24 | AD1: Saturday 23/03/24 | AE1: Sunday 24/03/24 | AF1: Monday 25/03/24 | AG1: Tuesday 26/03/25 | AH1: Wednesday 27/03/24 | AI1: Thursday 28/03/24 | AJ1: Friday 29/03/24 | AK1: Saturday 30/03/24 | AL1: Sunday 31/03/24 | AM1: Monday 01/04/2024 | AN1: Tuesday 02/04/2024 | AO1: Wednesday 03/04/2024 | AP1: Thursday 04/04/2024 | AQ1: Friday 05/04/2024 | AR1: Saturday 06/04/2024 | AS1: Sunday 07/04/2024 | AT1: Monday 08/04/2024 | AU1: Tuesday 09/04/2024 | AV1: Wednesday 10/04/2024 | AW1: Thursday 11/04/2024 | AX1: Friday 12/04/24 | AY1: Saturday 13/04/2024 | AZ1: Sunday 14/04/2024 | BA1: Monday 15/04/2024 | BB1: Tuesday 16/04/2024 | BC1: Wednesday 17/04/2024 | BD1: Thursday 18/04/2024 | BE1: Friday 19/04/24 | BF1: Saturday 20/04/2024 | BG1: Sunday 21/04/2024 | BH1: Monday 22/04/2024 | BI1: Tuesday 23/04/2024 | BJ1: Wednesday 24/04/2024 | BK1: Thursday 25/04/2024 | BL1: Friday 26/04/24 | BM1: Saturday 27/04/2024 | BN1: Sunday 28/04/2024 | BO1: Monday 29/04/2024 | BP1: Tuesday 30/04/2024 | BQ1: Wednesday 01/05/2024 | BR1: Thursday 02/05/2024 | BS1: Friday 03/05/24 | BT1: Saturday 04/05/2024 | BU1: Sunday 05/05/2024 | BV1: Monday 06/05/2024 | BW1: Tuesday 07/05/2024 | BX1: Wednesday 08/05/2024 | BY1: Thursday 09/05/2024 | BZ1: Friday 10/05/2024 | CA1: Saturday 11/05/2024 | CB1: Sunday 12/05/2024 | CC1: Monday 13/05/2024 | CD1: Tuesday 14/05/2024 | CE1: Wednesday 15/05/2024 | CF1: Thursday 16/05/2024 | CG1: Friday 17/05/24 | CH1: 45430 | CI1: 45431 | CJ1: 45432 | CK1: 45433 | CL1: 45434 | CM1: 45435 | CN1: 45436 | CO1: 45437 | CP1: 45438 | CQ1: 45439 | CR1: 45440 | CS1: 45441 | CT1: 45442 | CU1: 45443 | CV1: 45444 | CW1: 45445 | CX1: 45446 | CY1: 45447 | CZ1: 45448 | DA1: 45449 | DB1: 45450 | DC1: 45451 | DD1: 45452 | DE1: 45453 | DF1: 45454 | DG1: 45455 | DH1: 45456 | DI1: 45457 | DJ1: 45458 | DK1: 45459 | DL1: 45460 | DM1: 45461 | DN1: 45462 | DO1: 45463 | DP1: 45464 | DQ1: 45465 | DR1: 45466 | DS1: 45467 | DT1: 45468 | DU1: 45469 | DV1: 45470 | DW1: 45471 | DX1: 45472 | DY1: 45473 | DZ1: 45474 | EA1: 45475 | EB1: 45476 | EC1: 45477 | ED1: 45478 | EE1: 45479 | EF1: 45480 | EG1: 45481 | EH1: 45482 | EI1: 45483 | EJ1: 45484 | EK1: 45485 | EL1: 45486 | EM1: 45487 | EN1: 45488 | EO1: 45489 | EP1: 45490 | EQ1: 45491 | ER1: 45492 | ES1: 45493 | ET1: 45494 | EU1: 45495 | EV1: 45496 | EW1: 45497 | EX1: 45498 | EY1: 45499 | EZ1: 45500 | FA1: 45501 | FB1: 45502 | FC1: 45503 | FD1: 45504 | FE1: 45505 | FF1: 45506 | FG1: 45507 | FH1: 45508 | FI1: 45509 | FJ1: 45510 | FK1: 45511 | FL1: 45512 | FM1: 45513 | FN1: 45514 | FO1: 45515 | FP1: 45516 | FQ1: 45517 | FR1: 45518 | FS1: 45519 | FT1: 45520 | FU1: 45521 | FV1: 45522 | FW1: 45523 | FX1: 45524 | FY1: 45525 | FZ1: 45526 | GA1: 45527 | GB1: 45528 | GC1: 45529 | GD1: 45530 | GE1: 45531 | GF1: 45532 | GG1: 45533 | GH1: 45534 | GI1: 45535 | GJ1: 45536 | GK1: 45537 | GL1: 45538 | GM1: 45539 | GN1: 45540 | GO1: 45541 | GP1: 45542 | GQ1: 45543 | GR1: 45544 | GS1: 45545 | GT1: 45546 | GU1: 45547 | GV1: 45548 | GW1: 45549 | GX1: 45550 | GY1: 45551 | GZ1: 45552 | HA1: 45553 | HB1: 45554 | HC1: 45555 | HD1: 45556 | HE1: 45557 | HF1: 45558 | HG1: 45559 | HH1: 45560 | HI1: 45561 | HJ1: 45562 | HK1: 45563 | HL1: 45564 | HM1: 45565 | HN1: 45566 | HO1: 45567 | HP1: 45568 | HQ1: 45569 | HR1: 45570 | HS1: 45571 | HT1: 45572 | HU1: 45573 | HV1: 45574 | HW1: 45575 | HX1: 45576 | HY1: 45577 | HZ1: 45578 | IA1: 45579 | IB1: 45580 | IC1: 45581 | ID1: 45582 | IE1: 45583 | IF1: 45584 | IG1: 45585 | IH1: 45586 | II1: 45587 | IJ1: 45588 | IK1: 45589 | IL1: 45590 | IM1: 45591 | IN1: 45592 | IO1: 45593 | IP1: 45594 | IQ1: 45595 | IR1: 45596 | IS1: 45597 | IT1: 45598 | IU1: 45599 | IV1: 45600 | IW1: 45601 | IX1: 45602 | IY1: 45603 | IZ1: 45604 | JA1: 45605 | JB1: 45606 | JC1: 45607 | JD1: 45608 | JE1: 45609 | JF1: 45610 | JG1: 45611 | JH1: 45612 | JI1: 45613 | JJ1: 45614 | JK1: 45615 | JL1: 45616 | JM1: 45617 | JN1: 45618 | JO1: 45619 | JP1: 45620 | JQ1: 45621 | JR1: 45622 | JS1: 45623 | JT1: 45624 | JU1: 45625 | JV1: 45626 | JW1: 45627 | JX1: 45628 | JY1: 45629 | JZ1: 45630 | KA1: 45631 | KB1: 45632 | KC1: 45633 | KD1: 45634 | KE1: 45635 | KF1: 45636 | KG1: 45637 | KH1: 45638 | KI1: 45639 | KJ1: 45640 | KK1: 45641 | KL1: 45642 | KM1: 45643 | KN1: 45644 | KO1: 45645 | KP1: 45646 | KQ1: 45647 | KR1: 45648 | KS1: 45649 | KT1: 45650 | KU1: 45651 | KV1: 45652 | KW1: 45653 | KX1: 45654 | KY1: 45655 | KZ1: 45656 | LA1: 45657
A2: Service Desk
A3: Sarah Watkins | B3: Service Desk | C3: 1st Line | D3: Service Desk | E3: Service Desk | F3: Service Desk | G3: Service Desk | H3: Service Desk | K3: Service Desk | L3: Service Desk | M3: Service Desk | N3: Service Desk | O3: Service Desk | R3: Training | S3: Training | T3: Service Desk | U3: Service Desk | V3: Service Desk | Y3: Service Desk | Z3: Service Desk | AA3: Service Desk | AB3: Service Desk | AC3: Service Desk | AF3: Service Desk | AG3: Service Desk | AH3: Service Desk | AI3: Annual Leave | AJ3: BH | AM3: BH | AN3: Normal Work | AO3: Normal Work | AP3: Normal Work | AQ3: Normal Work | AT3: Normal Work | AU3: Normal Work | AV3: Normal Work | AW3: Normal Work | AX3: Normal Work | BA3: Normal Work | BB3: Normal Work | BC3: Normal Work | BD3: Normal Work | BE3: Leave | BH3: Normal Work | BI3: Normal Work | BJ3: Normal Work | BK3: Normal Work | BL3: Normal Work | BO3: Normal Work | BP3: Normal Work | BQ3: Normal Work | BR3: Normal Work | BS3: Normal Work | BV3: BH | BW3: Normal Work | BX3: Normal Work | BY3: Normal Work | BZ3: Normal Work | CC3: Normal Work | CD3: Normal Work | CE3: Normal Work | CF3: Normal Work | CG3: Normal Work | CJ3: Normal Work | CK3: Normal Work | CL3: Normal Work | CM3: Normal Work | CN3: Normal Work | CR3: Annual Leave | CS3: Normal Work | CT3: Normal Work | CU3: Normal Work | CX3: Normal Work | CY3: Normal Work | CZ3: Normal Work | DA3: Normal Work | DB3: Normal Work | DE3: Normal Work | DF3: Normal Work | DG3: Normal Work | DH3: Normal Work | DI3: Normal Work | DL3: Normal Work | DM3: Normal Work | DN3: Normal Work | DO3: Normal Work | DP3: Normal Work | DS3: Normal Work | DT3: Normal Work | DU3: Normal Work | DV3: Normal Work | DW3: Annual Leave | DZ3: Annual Leave | EA3: Annual Leave | EB3: Annual Leave | EC3: Annual Leave | ED3: Annual Leave | EG3: Normal Work | EH3: Normal Work | EI3: Normal Work | EJ3: Normal Work | EK3: Normal Work | EN3: Normal Work | EO3: Normal Work | EP3: Normal Work | EQ3: Normal Work | ER3: Normal Work | EU3: Annual Leave | EV3: Normal Work | EW3: Normal Work | EX3: Normal Work | EY3: Normal Work | FB3: Annual Leave | FC3: Normal Work | FD3: Normal Work | FE3: Normal Work | FF3: Normal Work | FI3: Annual Leave | FJ3: Normal Work | FK3: Normal Work | FL3: Normal Work | FM3: Normal Work | FP3: Annual Leave | FQ3: Annual Leave | FR3: Annual Leave | FS3: Normal Work | FT3: Normal Work | FW3: Annual Leave | FX3: Normal Work | FY3: Normal Work | FZ3: Normal Work | GA3: Normal Work | GE3: Normal Work | GF3: Normal Work | GG3: Normal Work | GH3: Annual Leave | GK3: Normal Work | GL3: Normal Work | GM3: Normal Work | GN3: Normal Work | GO3: Normal Work | GR3: Normal Work | GS3: Normal Work | GT3: Normal Work | GU3: Normal Work | GV3: Normal Work | GY3: Normal Work | GZ3: Normal Work | HA3: Normal Work | HB3: Normal Work | HC3: Normal Work | HF3: Normal Work | HG3: Normal Work | HH3: Normal Work | HI3: Normal Work | HJ3: Normal Work | HM3: Normal Work | HN3: Normal Work | HO3: Normal Work | HP3: Normal Work | HQ3: Normal Work | HT3: Normal Work | HU3: Normal Work | HV3: Normal Work | HW3: Normal Work | HX3: Normal Work | IA3: Normal Work | IB3: Normal Work | IC3: Normal Work | ID3: Normal Work | IE3: Normal Work | IH3: Normal Work | II3: Normal Work | IJ3: Normal Work | IK3: Normal Work | IL3: Annual Leave | IO3: Normal Work | IP3: Normal Work | IQ3: Normal Work | IR3: Normal Work | IS3: Normal Work | IV3: Normal Work | IW3: Normal Work | IX3: Normal Work | IY3: Normal Work | IZ3: Normal Work | JC3: Normal Work | JD3: Normal Work | JE3: Normal Work | JF3: Normal Work | JG3: Normal Work | JJ3: Normal Work | JK3: Normal Work | JL3: Normal Work | JM3: Normal Work | JN3: Normal Work | JQ3: Normal Work | JR3: Normal Work | JS3: Normal Work | JT3: Normal Work | JU3: Normal Work | JX3: Normal Work | JY3: Normal Work | JZ3: Normal Work | KA3: Normal Work | KB3: Normal Work | KE3: Normal Work | KF3: Normal Work | KG3: Normal Work | KH3: Normal Work | KI3: Normal Work | KL3: Normal Work | KM3: Normal Work | KN3: Normal Work | KO3: Normal Work | KP3: Normal Work | KS3: Normal Work | KT3: Annual Leave | KW3: Annual Leave | KZ3: Annual Leave | LA3: Annual Leave | MW3: Annual Leave | MX3: Annual Leave | MY3: Annual Leave | MZ3: Annual Leave | NA3: Annual Leave | QR3: Annual Leave | QS3: Annual Leave | QT3: Annual Leave | QU3: Annual Leave
A4: Jacob Martin | B4: Service Desk | C4: 1st Line | D4: Training | E4: Training | F4: Service Desk | G4: Exam / Service Desk | H4: Service Desk | K4: Training | L4: Training | M4: Service Desk | N4: Exam / Service Desk | O4: Service Desk | R4: PROJECTS | S4: PROJECTS | T4: Training | U4: Training | V4: Training | Y4: PROJECTS | Z4: PROJECTS | AA4: PROJECTS | AB4: Training | AC4: Training | AF4: Service Desk | AG4: Service Desk | AH4: PROJECTS | AI4: PROJECTS | AJ4: BH | AM4: BH | AN4: Projects | AO4: Projects | AP4: Annual Leave | AQ4: Annual Leave | AT4: Projects | AU4: Projects | AV4: Projects | AW4: Projects | AX4: Projects | BA4: Projects | BB4: Normal Work | BC4: Projects | BD4: Projects | BE4: Projects | BH4: Projects | BI4: Normal Work | BJ4: Normal Work | BK4: Normal Work | BL4: Normal Work | BO4: Normal Work | BP4: Normal Work | BQ4: Normal Work | BR4: Normal Work | BS4: Normal Work | BV4: BH | BW4: Normal Work | BX4: Normal Work | BY4: Normal Work | BZ4: Normal Work | CC4: Normal Work | CD4: Normal Work | CE4: Normal Work | CF4: Normal Work | CG4: Normal Work | CJ4: Normal Work | CK4: Normal Work | CL4: Projects | CM4: Normal Work | CN4: Normal Work | CR4: Annual Leave | CS4: Annual Leave | CT4: Annual Leave | CU4: Annual Leave | CX4: Normal Work | CY4: Normal Work | CZ4: Normal Work | DA4: Normal Work | DB4: Normal Work | DE4: Normal Work | DF4: Normal Work | DG4: Normal Work | DH4: Normal Work | DI4: Normal Work | DL4: Normal Work | DM4: Normal Work | DN4: Normal Work | DO4: Normal Work | DP4: Normal Work | DS4: Normal Work | DT4: Normal Work | DU4: Normal Work | DV4: Normal Work | DW4: Normal Work | DZ4: Normal Work | EA4: Normal Work | EB4: Normal Work | EC4: Normal Work | ED4: Normal Work | EG4: Normal Work | EH4: Normal Work | EI4: Normal Work | EJ4: Normal Work | EK4: Normal Work | EN4: Normal Work | EO4: Projects | EP4: Projects | EQ4: Normal Work | ER4: Normal Work | EU4: Annual Leave | EV4: Projects | EW4: Annual Leave | EX4: Annual Leave | EY4: Annual Leave | FB4: Normal Work | FC4: Normal Work | FD4: Normal Work | FE4: Normal Work | FF4: Annual Leave | FI4: Sickness | FJ4: Sickness | FK4: Normal Work | FL4: Normal Work | FM4: Normal Work | FP4: Normal Work | FQ4: Normal Work | FR4: Projects | FS4: Projects | FT4: Annual Leave | FW4: Annual Leave | FX4: Annual Leave | FY4: Annual Leave | FZ4: Annual Leave | GA4: Annual Leave | GE4: Normal Work | GF4: Normal Work | GG4: Normal Work | GH4: Normal Work | GK4: Normal Work | GL4: Normal Work | GM4: Normal Work | GN4: Normal Work | GO4: Normal Work | GR4: Normal Work | GS4: Normal Work | GT4: Normal Work | GU4: Normal Work | GV4: Normal Work | GY4: Normal Work | GZ4: Projects | HA4: Normal Work | HB4: Normal Work | HC4: Training | HF4: Normal Work | HG4: Normal Work | HH4: Normal Work | HI4: Normal Work | HJ4: Normal Work | HM4: Normal Work | HN4: Normal Work | HO4: Normal Work | HP4: Normal Work | HQ4: Normal Work | HT4: Normal Work | HU4: Normal Work | HV4: Normal Work | HW4: Normal Work | HX4: Normal Work | IA4: Normal Work | IB4: Normal Work | IC4: Sick | ID4: Normal Work | IE4: Normal Work | IH4: Normal Work | II4: Normal Work | IJ4: Normal Work | IK4: Normal Work | IL4: Normal Work | IO4: Normal Work | IP4: Normal Work | IQ4: Annual Leave | IR4: Annual Leave | IS4: Annual Leave | IV4: Normal Work | IW4: Normal Work | IX4: Normal Work | IY4: Normal Work | IZ4: Normal Work | JC4: Normal Work | JD4: Normal Work | JE4: GHC SD | JF4: GHC SD | JG4: GHC SD | JJ4: Normal Work | JK4: GHC SD | JL4: GHC SD | JM4: Normal Work | JN4: Normal Work | JQ4: GHC SD | JR4: Normal Work | JS4: Normal Work | JT4: Annual Leave | JU4: Annual Leave | JX4: Annual Leave | JY4: GHC SD | JZ4: GHC SD | KA4: GHC SD | KB4: GHC SD | KE4: GHC IT Audit | KF4: GHC IT Audit | KG4: GHC IT Audit | KH4: GHC IT Audit | KI4: GHC IT Audit | KL4: GHC IT Audit | KM4: GHC IT Audit | KN4: GHC IT Audit | KO4: GHC IT Audit | KP4: Normal Work | KQ4: On-call | KR4: On-call | KS4: Normal Work | KT4: Normal Work | KV4: On-Call | KW4: Annual Leave | KZ4: Normal Work | LA4: Normal Work
A5: Dan Carter | B5: Service Desk | C5: 2nd Line | D5: OST PROJECT | E5: OST PROJECT | F5: OST PROJECT | G5: OST PROJECT | H5: Annual Leave | K5: Annual Leave | L5: Service Desk | M5: Service Desk | N5: Service Desk | O5: Service Desk | R5: Service Desk | S5: Service Desk | T5: Service Desk | U5: Service Desk | V5: Service Desk | Y5: Service Desk | Z5: Service Desk | AA5: Service Desk | AB5: Service Desk | AC5: Annual Leave | AF5: Annual Leave | AG5: Service Desk | AH5: Service Desk | AI5: Annual Leave | AJ5: BH | AM5: BH | AN5: Normal Work | AO5: Normal Work | AP5: Normal Work | AQ5: Normal Work | AT5: Normal Work | AU5: Normal Work | AV5: Normal Work | AW5: Normal Work | AX5: Normal Work | BA5: Normal Work | BB5: Normal Work | BC5: Normal Work | BD5: Normal Work | BE5: Normal Work | BH5: Normal Work | BI5: Normal Work | BJ5: Normal Work | BK5: Normal Work | BL5: Normal Work | BO5: Annual Leave | BP5: Normal Work | BQ5: Normal Work | BR5: Normal Work | BS5: Normal Work | BV5: BH | BW5: Normal Work | BX5: Normal Work | BY5: Normal Work | BZ5: Normal Work | CC5: Normal Work | CD5: Normal Work | CE5: Normal Work | CF5: Normal Work | CG5: Normal Work | CJ5: A/L | CK5: A/L | CL5: Normal Work | CM5: Normal Work | CN5: Normal Work | CR5: Normal Work | CS5: Normal Work | CT5: Normal Work | CU5: Normal Work | CX5: Normal Work | CY5: Normal Work | CZ5: Normal Work | DA5: Normal Work | DB5: Normal Work | DE5: Annual Leave | DF5: Annual Leave | DG5: Annual Leave | DH5: Normal Work | DI5: Normal Work | DL5: Normal Work | DM5: Sick Leave | DN5: Normal Work | DO5: Normal Work | DP5: Annual Leave | DS5: Normal Work | DT5: Normal Work | DU5: Normal Work | DV5: Normal Work | DW5: Normal Work | DZ5: Normal Work | EA5: Normal Work | EB5: Normal Work | EC5: Normal Work | ED5: Normal Work | EG5: Normal Work | EH5: Normal Work | EI5: Normal Work | EJ5: Normal Work | EK5: Normal Work | EN5: Normal Work | EO5: Normal Work | EP5: Normal Work | EQ5: Normal Work | ER5: Normal Work | EU5: Normal Work | EV5: Normal Work | EW5: Normal Work | EX5: Normal Work | EY5: Normal Work | FB5: Normal Work | FC5: Normal Work | FD5: Normal Work | FE5: Normal Work | FF5: Normal Work | FI5: Annual Leave | FJ5: Normal Work | FK5: Normal Work | FL5: Normal Work | FM5: Normal Work | FP5: Normal Work | FQ5: Normal Work | FR5: Normal Work | FS5: Normal Work | FT5: Normal Work | FW5: Normal Work | FX5: Normal Work | FY5: Normal Work | FZ5: Normal Work | GA5: Normal Work | GE5: Normal Work | GF5: Normal Work | GG5: Normal Work | GH5: Normal Work | GK5: Normal Work | GL5: Normal Work | GM5: Normal Work | GN5: Normal Work | GO5: Normal Work | GR5: Annual Leave | GS5: Annual Leave | GT5: Annual Leave | GU5: Normal Work | GV5: Normal Work | GY5: Normal Work | GZ5: Normal Work | HA5: Normal Work | HB5: Normal Work | HC5: Normal Work | HF5: Normal Work | HG5: Normal Work | HH5: Normal Work | HI5: Normal Work | HJ5: Normal Work | HM5: Normal Work | HN5: Normal Work | HO5: Normal Work | HP5: Normal Work | HQ5: Normal Work | HT5: Normal Work | HU5: Normal Work | HV5: Normal Work | HW5: Normal Work | HX5: Normal Work | IA5: Normal Work | IB5: Normal Work | IC5: Normal Work | ID5: Normal Work | IE5: Normal Work | IH5: Normal Work | II5: Normal Work | IJ5: Normal Work | IK5: Normal Work | IL5: Normal Work | IO5: Normal Work | IP5: Normal Work | IQ5: Normal Work | IR5: Normal Work | IS5: Normal Work | IV5: Sick | IW5: Normal Work | IX5: Normal Work | IY5: Normal Work | IZ5: Normal Work | JC5: Normal Work | JD5: Normal Work | JE5: Normal Work | JF5: Normal Work | JG5: Normal Work | JJ5: Normal Work | JK5: Normal Work | JL5: Normal Work | JM5: Normal Work | JN5: Normal Work | JQ5: Normal Work | JR5: Normal Work | JS5: Normal Work | JT5: Normal Work | JU5: Normal Work | JX5: Normal Work | JY5: Normal Work | JZ5: GHC IT Audit | KA5: GHC IT Audit | KB5: Normal Work | KE5: Normal Work | KF5: Normal Work | KG5: GHC IT Audit | KH5: GHC IT Audit | KI5: Normal Work | KL5: Normal Work | KM5: Normal Work | KN5: Normal Work | KO5: Normal Work | KP5: Normal Work | KS5: Normal Work | KT5: Normal Work | KU5: On-Call | KW5: Normal Work | KX5: On-Call | KY5: On-Call | KZ5: Normal Work | LA5: Normal Work | LP5: Annual Leave | LQ5: Annual Leave | LR5: Annual Leave | LS5: Annual Leave | LT5: Annual Leave | LU5: Annual Leave | LV5: Annual Leave | LW5: Annual Leave | LX5: Annual Leave | LY5: Annual Leave | LZ5: Annual Leave | MA5: Annual Leave | MB5: Annual Leave | MC5: Annual Leave | MD5: Annual Leave
A6: Will Workman | B6: Service Desk | C6: 2nd Line | D6: Annual Leave | E6: Annual Leave | F6: Annual Leave | G6: Service Desk | H6: Service Desk | K6: Service Desk | L6: Service Desk | M6: Service Desk | N6: Service Desk | O6: Service Desk | R6: Service Desk | S6: Service Desk | T6: Service Desk | U6: Service Desk | V6: Service Desk | Y6: OST Project | Z6: OST Project | AA6: OST Project | AB6: OST Project | AC6: OST Project | AF6: OST Project | AG6: OST Project | AH6: OST Project | AI6: OST Project | AJ6: BH | AM6: BH | AN6: Normal Work | AO6: Normal Work | AP6: Normal Work | AQ6: Normal Work | AT6: OST Project | AU6: OST Project | AV6: OST Project | AW6: Normal Work | AX6: Normal Work | BA6: Normal Work | BB6: Normal Work | BC6: Normal Work | BD6: Normal Work | BE6: Normal Work | BH6: Normal Work | BI6: Normal Work | BJ6: Normal Work | BK6: Annual Leave | BL6: Normal Work | BO6: Normal Work | BP6: Normal Work | BQ6: Normal Work | BR6: Normal Work | BS6: Normal Work | BV6: BH | BW6: Normal Work | BX6: Normal Work | BY6: Normal Work | BZ6: Normal Work | CD6: Normal Work | CE6: Normal Work | CF6: Normal Work | CG6: Normal Work | CJ6: Normal Work | CK6: Normal Work | CL6: Normal Work | CM6: Normal Work | CN6: Normal Work | CX6: Normal Work | CY6: Normal Work | DA6: Normal Work | DB6: Normal Work | DL6: Normal Work | DM6: Normal Work | DN6: Normal Work | DO6: Normal Work | DP6: Normal Work | DT6: Normal Work | DU6: Normal Work | DV6: Normal Work | DW6: Normal Work | DZ6: Normal Work | EA6: Normal Work | EB6: Normal Work | EC6: Normal Work | ED6: Normal Work | EG6: Normal Work | EH6: Normal Work | EI6: Normal Work | EJ6: Normal Work | EN6: Normal Work | EO6: Normal Work | EP6: Normal Work | EQ6: Normal Work | ER6: Normal Work | EU6: Normal Work | EV6: Normal Work | EW6: Normal Work | EX6: Normal Work | FB6: Normal Work | FC6: Normal Work | FD6: Normal Work | FE6: Normal Work | FF6: Normal Work | FJ6: Normal Work | FK6: Normal Work | FP6: Normal Work | FQ6: Normal Work | FR6: Normal Work | FS6: Normal Work | FT6: Normal Work | GE6: Normal Work | GF6: Normal Work | GG6: Normal Work | GH6: Normal Work | GK6: Normal Work | GL6: Normal Work | GM6: Normal Work | GN6: Normal Work | GO6: Normal Work | GY6: Normal Work | GZ6: Normal Work | HA6: Normal Work | HB6: Normal Work | HT6: Normal Work | HU6: Normal Work | HV6: Normal Work | HW6: Normal Work | HX6: Normal Work | IA6: Normal Work | IB6: Normal Work | IC6: Normal Work | ID6: Normal Work | IE6: Normal Work | II6: Normal Work | IJ6: Normal Work | IK6: Normal Work | IL6: Normal Work | IO6: Normal Work | IP6: Normal Work | IQ6: Normal Work | IW6: Normal Work | IX6: Normal Work | IY6: Normal Work | IZ6: Normal Work | JC6: Normal Work | JD6: Normal Work | JJ6: Normal Work | JK6: Normal Work | JL6: Normal Work | JM6: Normal Work | JZ6: Normal Work | KB6: Normal Work | KT6: Normal Work
A7: James Norman | B7: Service Desk | C7: 3rd Line | D7: Service Desk | E7: Service Desk | F7: Service Desk | G7: Service Desk | H7: Service Desk | K7: Service Desk | L7: Service Desk | M7: Annual Leave | N7: Service Desk | O7: Annual Leave | R7: OST PROJECT | S7: OST PROJECT | T7: Service Desk | U7: Service Desk | V7: Service Desk | Y7: GHC Server Day | Z7: Service Desk | AA7: Training | AB7: Training | AC7: Service Desk | AF7: Service Desk | AG7: Service Desk | AH7: Service Desk | AI7: Service Desk | AJ7: BH | AM7: BH | AN7: Normal Work | AO7: OST Project | AP7: OST Project | AQ7: OST Project | AT7: Normal Work | AU7: Normal Work | AV7: Normal Work | AW7: Normal Work | AX7: Annual Leave | BA7: Annual Leave | BB7: Annual Leave | BC7: Annual Leave | BD7: Annual Leave | BE7: Annual Leave | BH7: OST Project | BI7: OST Project | BJ7: OST Project | BK7: OST Project | BL7: OST Project | BO7: Normal Work | BP7: Normal Work | BQ7: Normal Work | BR7: Normal Work | BS7: Normal Work | BV7: BH | BW7: Normal Work | BX7: Normal Work | BY7: Normal Work | BZ7: Normal Work | CC7: Normal Work | CD7: Normal Work | CE7: Normal Work | CF7: Normal Work | CG7: Normal Work | CJ7: Normal Work | CK7: Normal Work | CL7: Normal Work | CM7: Normal Work | CN7: Normal Work | CR7: Annual Leave | CS7: Normal Work | CT7: Normal Work | CU7: Normal Work | CX7: Normal Work | CY7: Normal Work | CZ7: Normal Work | DA7: Normal Work | DB7: Normal Work | DE7: Normal Work | DF7: Normal Work | DG7: Normal Work | DH7: Normal Work | DI7: Normal Work | DL7: Normal Work | DM7: Normal Work | DN7: Normal Work | DO7: Normal Work | DP7: Normal Work | DS7: Normal Work | DT7: Normal Work | DU7: Normal Work | DV7: Normal Work | DW7: Normal Work | DZ7: Normal Work | EA7: Normal Work | EB7: Normal Work | EC7: Normal Work | ED7: Normal Work | EG7: Normal Work | EH7: Normal Work | EI7: Normal Work | EJ7: Normal Work | EK7: Annual Leave | EN7: Normal Work | EO7: Normal Work | EP7: Normal Work | EQ7: Normal Work | ER7: Normal Work | EU7: Normal Work | EV7: Normal Work | EW7: Normal Work | EX7: Normal Work | EY7: Annual Leave | FB7: Normal Work | FC7: Normal Work | FD7: Normal Work | FE7: Normal Work | FF7: Normal Work | FI7: Normal Work | FJ7: Normal Work | FK7: Normal Work | FL7: Annual Leave | FM7: Annual Leave | FP7: Normal Work | FQ7: Normal Work | FR7: Normal Work | FS7: Normal Work | FT7: Normal Work | FW7: Normal Work | FX7: Normal Work | FY7: Normal Work | FZ7: Normal Work | GA7: Annual Leave | GE7: Normal Work | GF7: Normal Work | GG7: Normal Work | GH7: Normal Work | GK7: Normal Work | GL7: Annual Leave | GM7: Normal Work | GN7: Normal Work | GO7: Normal Work | GR7: Normal Work | GS7: Normal Work | GT7: Normal Work | GU7: Normal Work | GV7: Normal Work | GY7: Normal Work | GZ7: Normal Work | HA7: Normal Work | HB7: Normal Work | HC7: Training | HF7: Normal Work | HG7: Normal Work | HH7: Normal Work | HI7: Annual Leave | HJ7: Annual Leave | HM7: Annual Leave | HN7: Annual Leave | HO7: Normal Work | HP7: Normal Work | HQ7: Normal Work | HT7: Normal Work | HU7: Normal Work | HV7: Normal Work | HW7: Normal Work | HX7: Normal Work | IA7: Normal Work | IB7: Normal Work | IC7: Normal Work | ID7: Normal Work | IE7: Normal Work | IH7: Annual Leave | II7: Normal Work | IJ7: Normal Work | IK7: Normal Work | IL7: Normal Work | IO7: Normal Work | IP7: Normal Work | IQ7: Normal Work | IR7: Normal Work | IS7: Normal Work | IV7: Normal Work | IW7: Normal Work | IX7: Normal Work | IY7: Normal Work | IZ7: Normal Work | JC7: Normal Work | JD7: Normal Work | JE7: GHC SD | JF7: GHC SD | JG7: GHC SD | JJ7: Normal Work | JK7: Normal Work | JL7: Normal Work | JM7: GHC SD | JN7: GHC SD | JQ7: Normal Work | JR7: GHC SD | JS7: GHC SD | JT7: GHC SD | JU7: GHC SD | JX7: Sick Leave | JY7: Normal Work | JZ7: Normal Work | KA7: Normal Work | KB7: Normal Work | KE7: GHC SD | KF7: GHC SD | KG7: GHC SD | KH7: GHC SD | KI7: GHC SD | KL7: Normal Work | KM7: Normal Work | KN7: Normal Work | KO7: Annual Leave | KP7: Annual Leave | KS7: Normal Work | KT7: Normal Work | KW7: Annual Leave | KZ7: Annual Leave | LA7: Annual Leave
A8: Luke Rothwell | B8: Service Desk | C8: 3rd Line | D8: Service Desk | E8: Service Desk | F8: Service Desk | G8: Service Desk | H8: Service Desk | K8: Service Desk | L8: Service Desk | M8: Service Desk | N8: Service Desk | O8: Service Desk | R8: Service Desk | S8: Service Desk | T8: Training | U8: Training | V8: Service Desk | Y8: Ingenia on-site | Z8: GHC Server Day | AA8: Service Desk | AB8: Service Desk | AC8: Projects | AF8: Service Desk | AG8: Service Desk | AH8: Service Desk | AI8: Service Desk | AJ8: BH | AM8: BH | AN8: Normal Work | AO8: Projects | AP8: Normal Work | AQ8: Normal Work | AT8: Normal Work | AU8: Normal Work | AV8: Normal Work | AW8: Normal Work | AX8: Normal Work | BA8: Normal Work | BB8: Normal Work | BC8: Normal Work | BD8: Normal Work | BE8: Normal Work | BH8: Normal Work | BI8: Normal Work | BJ8: Normal Work | BK8: Normal Work | BL8: Normal Work | BO8: Annual Leave | BP8: Annual Leave | BQ8: Annual Leave | BR8: Annual Leave | BS8: Annual Leave | BV8: BH | BW8: Annual Leave | BX8: Normal Work | BY8: Normal Work | BZ8: Normal Work | CC8: Normal Work | CD8: Normal Work | CE8: Normal Work | CF8: Annual Leave | CG8: Normal Work | CJ8: Normal Work | CK8: Normal Work | CL8: Normal Work | CM8: Normal Work | CN8: Normal Work | CR8: Training | CS8: Training | CT8: Training | CU8: Normal Work | CX8: Normal Work | CY8: Normal Work | CZ8: Normal Work | DA8: OST Work | DB8: Normal Work | DE8: Annual Leave | DF8: Annual Leave | DG8: Annual Leave | DH8: Annual Leave | DI8: Annual Leave | DL8: Annual Leave | DM8: Annual Leave | DN8: Normal Work | DO8: OST Work | DP8: Normal Work | DS8: Normal Work | DT8: Normal Work | DU8: Normal Work | DV8: Normal Work | DW8: Normal Work | DZ8: Normal Work | EA8: Normal Work | EB8: Normal Work | EC8: Normal Work | ED8: Annual Leave | EG8: Normal Work | EH8: Normal Work | EI8: Normal Work | EJ8: Normal Work | EK8: Normal Work | EN8: Normal Work | EO8: Normal Work | EP8: Normal Work | EQ8: Normal Work | ER8: Normal Work | EU8: Normal Work | EV8: Normal Work | EW8: Normal Work | EX8: Training | EY8: Training | FB8: Normal Work | FC8: Normal Work | FD8: Normal Work | FE8: Normal Work | FF8: Normal Work | FI8: Normal Work | FJ8: Normal Work | FK8: Normal Work | FL8: Normal Work | FM8: Normal Work | FP8: Normal Work | FQ8: Normal Work | FR8: Normal Work | FS8: Normal Work | FT8: Normal Work | FW8: Normal Work | FX8: Normal Work | FY8: Normal Work | FZ8: Normal Work | GA8: Normal Work | GE8: Normal Work | GF8: Normal Work | GG8: Normal Work | GH8: Normal Work | GK8: Normal Work | GL8: Normal Work | GM8: Normal Work | GN8: Normal Work | GO8: Normal Work | GR8: Normal Work | GS8: Normal Work | GT8: Normal Work | GU8: Normal Work | GV8: Normal Work | GY8: Normal Work | GZ8: Normal Work | HA8: Normal Work | HB8: Normal Work | HC8: Training | HF8: Annual Leave | HG8: Annual Leave | HH8: Annual Leave | HI8: Annual Leave | HJ8: Annual Leave | HM8: Annual Leave | HN8: Annual Leave | HO8: Annual Leave | HP8: Normal Work | HQ8: Normal Work | HT8: Normal Work | HU8: Normal Work | HV8: Normal Work | HW8: Normal Work | HX8: Normal Work | IA8: Normal Work | IB8: Normal Work | IC8: Normal Work | ID8: Normal Work | IE8: Normal Work | IH8: Normal Work | II8: Normal Work | IJ8: Normal Work | IK8: Normal Work | IL8: Normal Work | IO8: Normal Work | IP8: Normal Work | IQ8: Normal Work | IR8: Normal Work | IS8: Normal Work | IV8: Normal Work | IW8: Normal Work | IX8: Normal Work | IY8: Normal Work | IZ8: Normal Work | JC8: Normal Work | JD8: Normal Work | JE8: Normal Work | JF8: Normal Work | JG8: Normal Work | JJ8: Normal Work | JK8: Normal Work | JL8: Normal Work | JM8: Normal Work | JN8: Normal Work | JQ8: Normal Work | JR8: Normal Work | JS8: Normal Work | JT8: Normal Work | JU8: Normal Work | JX8: Normal Work | JY8: Normal Work | JZ8: Normal Work | KA8: Normal Work | KB8: Annual Leave | KE8: Training | KF8: Training | KG8: Training | KH8: Training | KI8: Normal Work | KL8: Normal Work | KM8: Normal Work | KN8: Normal Work | KO8: Normal Work | KP8: Normal Work | KQ8: On-call | KR8: On-call | KS8: Normal Work | KT8: Normal Work | KW8: Normal Work | KZ8: Annual Leave | LA8: Annual Leave
A9: Ben Lockhart | B9: Projects | C9: Projects | D9: Normal Work | E9: Normal Work | F9: Normal Work | G9: Normal Work | H9: Normal Work | K9: Normal Work | L9: Normal Work | M9: Normal Work | N9: Normal Work | O9: Normal Work | R9: Normal Work | S9: Normal Work | T9: Normal Work | U9: Normal Work | V9: Normal Work | Y9: Normal Work | Z9: Normal Work | AA9: Normal Work | AB9: Normal Work | AC9: Normal Work | AF9: Normal Work | AG9: Normal Work | AH9: Normal Work | AI9: Normal Work | AJ9: BH | AM9: BH | AN9: Annual Leave | AO9: Annual Leave | AP9: Annual Leave | AQ9: Annual Leave | AT9: Yondr | AU9: Yondr | AV9: Yondr | AW9: Yondr | AX9: Yondr | BA9: Yondr | BB9: Yondr | BC9: Yondr | BD9: Yondr | BE9: Yondr | BH9: Yondr | BI9: Yondr | BJ9: Yondr | BK9: Yondr | BL9: Yondr | BO9: Normal Work | BP9: Normal Work | BQ9: Normal Work | BR9: Normal Work | BS9: Normal Work | BV9: BH | BW9: Normal Work | BX9: Normal Work | BY9: Normal Work | BZ9: Normal Work | CC9: Normal Work | CD9: Normal Work | CE9: Normal Work | CF9: Normal Work | CG9: Normal Work | CJ9: Normal Work | CK9: Normal Work | CL9: Normal Work | CM9: Normal Work | CN9: Normal Work | CR9: Normal Work | CS9: Normal Work | CT9: Normal Work | CU9: Normal Work | CX9: Normal Work | CY9: Normal Work | CZ9: Normal Work | DA9: Normal Work | DB9: Normal Work | DE9: Normal Work | DF9: Normal Work | DG9: Normal Work | DH9: Normal Work | DI9: Normal Work | DL9: Normal Work | DM9: Normal Work | DN9: Normal Work | DO9: Normal Work | DP9: Normal Work | DS9: Normal Work | DT9: Normal Work | DU9: Normal Work | DV9: Normal Work | DW9: Normal Work | DZ9: Normal Work | EA9: Normal Work | EB9: Normal Work | EC9: Normal Work | ED9: Normal Work | EG9: Normal Work | EH9: Normal Work | EI9: Normal Work | EJ9: Normal Work | EK9: Annual Leave | EN9: Annual Leave | EO9: Normal Work | EP9: Normal Work | EQ9: Normal Work | ER9: Normal Work | EU9: Annual Leave | EV9: Projects | EW9: Projects | EX9: Training | EY9: Training | FB9: Normal Work | FC9: Projects | FD9: Projects | FE9: Projects | FF9: Projects | FI9: Projects | FJ9: Normal Work | FK9: Normal Work | FL9: Normal Work | FM9: Annual Leave | FP9: Annual Leave | FQ9: Annual Leave | FR9: Annual Leave | FS9: Annual Leave | FT9: Annual Leave | FW9: Annual Leave | FX9: Annual Leave | FY9: Annual Leave | FZ9: Annual Leave | GA9: Annual Leave | GE9: Normal Work | GF9: Normal Work | GG9: Normal Work | GH9: Normal Work | GK9: Normal Work | GL9: Normal Work | GM9: Normal Work | GN9: Normal Work | GO9: Normal Work | GR9: Normal Work | GS9: Normal Work | GT9: Normal Work | GU9: Normal Work | GV9: Normal Work | GY9: Normal Work | GZ9: Normal Work | HA9: Normal Work | HB9: Normal Work | HC9: Training | HF9: Normal Work | HG9: Normal Work | HH9: Normal Work | HI9: Training | HJ9: Training | HM9: Normal Work | HN9: Normal Work | HO9: Normal Work | HP9: Normal Work | HQ9: Normal Work | HT9: Normal Work | HU9: Normal Work | HV9: Normal Work | HW9: Normal Work | HX9: Normal Work | IA9: Normal Work | IB9: Normal Work | IC9: Normal Work | ID9: Normal Work | IE9: Normal Work | IH9: Normal Work | II9: Normal Work | IJ9: Normal Work | IK9: Normal Work | IL9: Normal Work | IO9: Normal Work | IP9: Normal Work | IQ9: Normal Work | IR9: Normal Work | IS9: Normal Work | IV9: Normal Work | IW9: Normal Work | IX9: Normal Work | IY9: Normal Work | IZ9: Annual Leave | JC9: Annual Leave | JD9: Annual Leave | JE9: Annual Leave | JF9: Annual Leave | JG9: Annual Leave | JJ9: Normal Work | JK9: Normal Work | JL9: Normal Work | JM9: Normal Work | JN9: Normal Work | JQ9: Normal Work | JR9: Normal Work | JS9: Normal Work | JT9: Normal Work | JU9: Normal Work | JX9: Normal Work | JY9: Normal Work | JZ9: Normal Work | KA9: Normal Work | KB9: Normal Work | KE9: Training | KF9: Training | KG9: Training | KH9: Training | KI9: Normal Work | KL9: Normal Work | KM9: Normal Work | KN9: Normal Work | KO9: Normal Work | KP9: Normal Work | KS9: Annual Leave | KT9: Annual Leave | KW9: Annual Leave | KZ9: Normal Work | LA9: Normal Work
A10: Tom Harber | B10: Service Desk | C10: Service | AT10: Projects | AU10: Normal Work | AV10: Normal Work | AW10: Normal Work | AX10: Normal Work | BA10: Normal Work | BB10: Normal Work | BC10: Normal Work | BD10: Normal Work | BE10: Normal Work | BH10: College | BI10: College | BJ10: College | BK10: College | BL10: College | CC10: Illness | CD10: Normal Work | CE10: Normal Work | CF10: Normal Work | CG10: Normal Work | CJ10: Normal Work | CK10: Normal Work | CL10: Normal Work | CM10: Normal Work | CN10: Normal Work | CR10: Normal Work | CS10: Normal Work | CT10: Normal Work | CU10: Normal Work | CX10: College | CY10: College | CZ10: College | DA10: College | DB10: College | DE10: Normal Work | DF10: Normal Work | DG10: Normal Work | DH10: Normal Work | DI10: Normal Work | DL10: Normal Work | DM10: Normal Work | DN10: Normal Work | DO10: Normal Work | DP10: Normal Work | DS10: Normal Work | DT10: Normal Work | DU10: Normal Work | DV10: Normal Work | DW10: Normal Work | DZ10: Normal Work | EA10: Normal Work | EB10: Normal Work | EC10: Normal Work | ED10: Normal Work | EG10: College | EH10: College | EI10: College | EJ10: College | EK10: College | EN10: Normal Work | EO10: Normal Work | EP10: Normal Work | EQ10: Absent | ER10: Absent | FI10: Annual Leave | FJ10: Annual Leave | FK10: Annual Leave | FL10: Annual Leave | FM10: Annual Leave | FP10: Normal Work | FQ10: Normal Work | FR10: Normal Work | FS10: Normal Work | FT10: Normal Work | FW10: Normal Work | FX10: Normal Work | FY10: Normal Work | FZ10: Normal Work | GA10: Normal Work | GE10: Normal Work | GF10: Normal Work | GG10: Normal Work | GH10: Normal Work | GK10: Annual Leave | GL10: Normal Work | GM10: Normal Work | GN10: Normal Work | GO10: Normal Work | GR10: Annual Leave | GS10: Annual Leave | GT10: Annual Leave | GU10: Annual Leave | GV10: Annual Leave | GY10: Annual Leave | GZ10: Annual Leave | HA10: Annual Leave | HB10: Annual Leave | HC10: Annual Leave | HF10: Normal Work | HG10: Normal Work | HH10: Normal Work | HI10: Normal Work | HJ10: Normal Work | HM10: Normal Work | HN10: Normal Work | HO10: Normal Work | HP10: Normal Work | HQ10: Normal Work | HT10: Normal Work | HU10: Normal Work | HV10: Normal Work | HW10: Normal Work | HX10: Normal Work | IA10: Normal Work | IB10: Normal Work | IC10: Normal Work | ID10: Normal Work | IE10: Normal Work | IH10: Normal Work | II10: Normal Work | IJ10: Normal Work | IK10: Normal Work | IL10: Normal Work | IO10: Normal Work | IP10: Normal Work | IQ10: Normal Work | IR10: Normal Work | IS10: Normal Work | IV10: Normal Work | IW10: Normal Work | IX10: Normal Work | IY10: Normal Work | IZ10: Normal Work | JC10: Normal Work | JD10: Normal Work | JE10: Normal Work | JF10: Normal Work | JG10: Normal Work | JJ10: Normal Work | JK10: Normal Work | JL10: Normal Work | JM10: Normal Work | JN10: Normal Work | JQ10: Normal Work | JR10: Normal Work | JS10: Normal Work | JT10: Normal Work | JU10: Normal Work | JX10: GHC IT Audit | JY10: GHC IT Audit | JZ10: GHC IT Audit | KA10: GHC IT Audit | KB10: GHC IT Audit | KE10: Annual Leave | KF10: Annual Leave | KG10: Annual Leave | KH10: Annual Leave | KI10: Annual Leave | KL10: Annual Leave | KM10: GHC IT Audit | KN10: GHC IT Audit | KO10: GHC IT Audit | KP10: GHC IT Audit | KS10: GHC IT Audit | KT10: GHC IT Audit | KW10: Annual Leave | KZ10: GHC IT Audit | LA10: GHC IT Audit
A11: OST BaB
A12: Eddie Beebee | B12: Build-a-Bear | C12: OST | D12: Normal Work | E12: Normal Work | F12: Normal Work | G12: Normal Work | H12: Normal Work | K12: Normal Work | L12: Normal Work | M12: Normal Work | N12: Normal Work | O12: Normal Work | R12: Normal Work | S12: Normal Work | T12: Normal Work | U12: Ingenia VPN | V12: Normal Work | Y12: Normal Work | Z12: Normal Work | AA12: Normal Work | AB12: Normal Work | AC12: Normal Work | AF12: Training | AG12: Training | AH12: Normal Work | AI12: Normal Work | AJ12: BH | AM12: BH | AN12: Normal Work | AQ12: Normal Work | AT12: Normal Work | AU12: Normal Work | AV12: Normal Work | AW12: Normal Work | AX12: Normal Work | BA12: Normal Work | BB12: Normal Work | BC12: Normal Work | BD12: Normal Work | BE12: Normal Work | BH12: Normal Work | BI12: Normal Work | BJ12: Normal Work | BK12: Normal Work | BL12: Normal Work | BO12: Normal Work | BP12: Normal Work | BQ12: Normal Work | BR12: Normal Work | BS12: Normal Work | BV12: BH | BW12: Normal Work | BX12: Normal Work | BY12: Normal Work | BZ12: Normal Work | CC12: Normal Work | CD12: Normal Work | CE12: Normal Work | CF12: Normal Work | CG12: Normal Work | CJ12: Normal Work | CK12: Normal Work | CL12: Normal Work | CM12: Normal Work | CN12: Normal Work | CR12: Service Desk | CS12: Normal Work | CT12: Service Desk | CU12: Normal Work | CX12: Normal Work | CY12: Normal Work | CZ12: Normal Work | DA12: Normal Work | DB12: Normal Work | DE12: Annual Leave | DF12: Normal Work | DG12: Normal Work | DH12: Normal Work | DI12: Normal Work | DL12: Annual Leave | DM12: Normal Work | DN12: Normal Work | DO12: Normal Work | DP12: Annual Leave | DS12: Normal Work | DT12: Normal Work | DU12: Annual Leave | DV12: Normal Work | DW12: Normal Work | DZ12: Annual Leave | EA12: Normal Work | EB12: Normal Work | EC12: Normal Work | ED12: Normal Work | EG12: Normal Work | EH12: Normal Work | EI12: Normal Work | EJ12: Annual Leave | EK12: Annual Leave | EN12: Annual Leave | EO12: Normal Work | EP12: Normal Work | EQ12: Normal Work | ER12: Normal Work | EU12: Normal Work | EV12: Normal Work | EW12: Normal Work | EX12: Normal Work | EY12: Normal Work | FB12: Normal Work | FC12: Normal Work | FD12: Normal Work | FE12: Normal Work | FF12: Annual Leave | FI12: Annual Leave | FJ12: Annual Leave | FK12: Annual Leave | FL12: Annual Leave | FM12: Annual Leave | FP12: Annual Leave | FQ12: Normal Work | FR12: Projects | FS12: Normal Work | FT12: Normal Work | FW12: Normal Work | FX12: Normal Work | FY12: Normal Work | FZ12: Normal Work | GA12: Normal Work | GE12: Normal Work | GF12: Normal Work | GG12: Normal Work | GH12: Normal Work | GK12: Normal Work | GL12: Projects | GM12: Projects | GN12: Normal Work | GO12: Normal Work | GR12: Normal Work | GS12: Normal Work | GT12: Normal Work | GU12: Normal Work | GV12: Normal Work | GY12: Normal Work | GZ12: Normal Work | HA12: Normal Work | HB12: Normal Work | HC12: Normal Work | HF12: Normal Work | HG12: Normal Work | HH12: Normal Work | HI12: Normal Work | HJ12: Annual Leave | HM12: Annual Leave | HN12: Normal Work | HO12: Normal Work | HP12: Normal Work | HQ12: Normal Work | HT12: Annual Leave | HU12: Normal Work | HV12: Normal Work | HW12: Normal Work | HX12: Normal Work | IA12: Normal Work | IB12: Normal Work | IC12: Normal Work | ID12: Normal Work | IE12: Normal Work | IH12: Normal Work | II12: Normal Work | IJ12: Normal Work | IK12: Training | IL12: Training | IO12: Normal Work | IP12: Normal Work | IQ12: Normal Work | IR12: Normal Work | IS12: Normal Work | IV12: Normal Work | IW12: Normal Work | IX12: Normal Work | IY12: Normal Work | IZ12: Normal Work | JC12: Normal Work | JD12: Normal Work | JE12: Normal Work | JF12: Normal Work | JG12: Normal Work | JJ12: Normal Work | JK12: Normal Work | JL12: Normal Work | JM12: Normal Work | JN12: Annual Leave | JQ12: Normal Work | JR12: Normal Work | JS12: Normal Work | JT12: Normal Work | JU12: Normal Work | JX12: Normal Work | JY12: Normal Work | JZ12: Normal Work | KA12: Normal Work | KB12: GHC IT Audit | KE12: GHC IT Audit | KF12: Normal Work | KG12: 2088 Oxford Street | KH12: 2088 Oxford Street | KI12: GHC IT Audit | KL12: GHC IT Audit | KM12: 2088 Oxford Street | KN12: 2088 Oxford Street | KO12: 2088 Oxford Street | KP12: 2088 Oxford Street | KS12: Normal Work | KT12: Normal Work | KW12: Annual Leave | KZ12: Normal Work | LA12: Normal Work
A13: Jake Vardy | B13: Build-a-Bear | C13: OST | D13: Normal Work | E13: Normal Work | F13: Normal Work | G13: Normal Work | H13: Normal Work | K13: Normal Work | L13: Normal Work | M13: Normal Work | N13: Normal Work | O13: Normal Work | R13: Normal Work | S13: Normal Work | T13: Normal Work | U13: Normal Work | V13: Normal Work | Y13: Normal Work | Z13: Normal Work | AA13: Normal Work | AB13: Normal Work | AC13: Normal Work | AF13: Normal Work | AG13: Normal Work | AH13: Normal Work | AI13: Normal Work | AJ13: BH | AM13: BH | AT13: Normal Work | AU13: Normal Work | AV13: Normal Work | AW13: Normal Work | AX13: Normal Work | BA13: Normal Work | BB13: Normal Work | BC13: Normal Work | BD13: Normal Work | BE13: Normal Work | BH13: Normal Work | BI13: Normal Work | BJ13: Normal Work | BK13: Normal Work | BL13: Normal Work | BO13: Normal Work | BP13: Normal Work | BQ13: Normal Work | BR13: Normal Work | BS13: Normal Work | BV13: BH | BW13: Left | BX13: Left | BY13: Left | BZ13: Left | CD13: Normal Work | DE13: Normal Work | DM13: Normal Work | DS13: Normal Work | DT13: Normal Work | EA13: Normal Work | EB13: Normal Work | EC13: Normal Work | ED13: Normal Work | EG13: Normal Work | EH13: Normal Work | EI13: Normal Work | EO13: Normal Work | EP13: Normal Work | EQ13: Normal Work | ER13: Normal Work | EU13: Normal Work | EV13: Normal Work | EW13: Normal Work | EX13: Normal Work | EY13: Normal Work | FB13: Normal Work | FC13: Normal Work | FD13: Normal Work | FE13: Normal Work | FW13: Normal Work | FX13: Normal Work | FY13: Normal Work | FZ13: Normal Work | GA13: Normal Work | GE13: Normal Work | GF13: Normal Work | GG13: Normal Work | GH13: Normal Work | GK13: Normal Work | GL13: Normal Work | GM13: Normal Work | GN13: Normal Work | GO13: Normal Work | GR13: Normal Work | GS13: Normal Work | GT13: Normal Work | GU13: Normal Work | GV13: Normal Work | GY13: Normal Work | GZ13: Normal Work | HA13: Normal Work | HB13: Normal Work | HC13: Normal Work | HF13: Normal Work | HG13: Normal Work | HH13: Normal Work | HI13: Normal Work | HN13: Normal Work | HO13: Normal Work | HP13: Normal Work | HQ13: Normal Work | HT13: Normal Work | HU13: Normal Work | HV13: Normal Work | HW13: Normal Work | HX13: Normal Work | IA13: Normal Work | IB13: Normal Work | IC13: Normal Work | ID13: Normal Work | IE13: Normal Work | IH13: Normal Work | II13: Normal Work | IJ13: Normal Work | IK13: Normal Work | IL13: Normal Work | IQ13: Normal Work | JC13: Normal Work | JD13: Normal Work | JE13: Normal Work | JF13: Normal Work | JG13: Normal Work | JJ13: Normal Work | JK13: Normal Work | JL13: Normal Work | JM13: Normal Work | JQ13: Normal Work | JR13: Normal Work | JS13: Normal Work | JU13: Normal Work | JX13: Normal Work | JY13: Normal Work | JZ13: Normal Work | KA13: Normal Work | KB13: Normal Work | KS13: Normal Work
A14: Alex Walton | B14: Build-a-Bear | C14: OST | CC14: Induction | CD14: Induction | CE14: Induction | CF14: Induction | CG14: Induction | CJ14: Training | CK14: Training | CL14: Normal Work | CM14: Normal Work | CN14: Normal Work | CR14: Normal Work | CS14: Normal Work | CT14: Normal Work | CU14: Normal Work | CX14: Annual Leave | CY14: Annual Leave | CZ14: Annual Leave | DA14: Annual Leave | DB14: Annual Leave | DE14: Normal Work | DF14: Normal Work | DG14: Normal Work | DH14: Projects | DI14: Normal Work | DL14: Normal Work | DM14: Service Desk | DN14: Normal Work | DO14: Normal Work | DP14: Normal Work | DS14: Normal Work | DT14: Normal Work | DU14: Normal Work | DV14: Normal Work | DW14: Normal Work | DZ14: Normal Work | EA14: Normal Work | EB14: Normal Work | EC14: Normal Work | ED14: Normal Work | EG14: Normal Work | EH14: Normal Work | EI14: Normal Work | EJ14: Normal Work | EK14: Normal Work | EN14: Normal Work | EO14: Normal Work | EP14: Normal Work | EQ14: Normal Work | ER14: Normal Work | EU14: Normal Work | EV14: Normal Work | EW14: Normal Work | EX14: Normal Work | EY14: Annual Leave | FB14: Normal Work | FC14: Normal Work | FD14: Normal Work | FE14: Normal Work | FF14: Normal Work | FI14: Normal Work | FJ14: Normal Work | FK14: Normal Work | FL14: Normal Work | FM14: Normal Work | FP14: Normal Work | FQ14: Normal Work | FR14: Normal Work | FS14: Normal Work | FT14: Normal Work | FW14: Normal Work | FX14: Normal Work | FY14: Normal Work | FZ14: Normal Work | GA14: Normal Work | GE14: Normal Work | GF14: Projects | GG14: Normal Work | GH14: Normal Work | GK14: Normal Work | GL14: Normal Work | GM14: Normal Work | GN14: Normal Work | GO14: Normal Work | GR14: Normal Work | GS14: Normal Work | GT14: Normal Work | GU14: Normal Work | GV14: Normal Work | GY14: Normal Work | GZ14: Normal Work | HA14: Normal Work | HB14: Normal Work | HC14: Normal Work | HF14: Normal Work | HG14: Normal Work | HH14: Normal Work | HI14: Normal Work | HJ14: Normal Work | HM14: Normal Work | HN14: Normal Work | HO14: Normal Work | HP14: Normal Work | HQ14: Normal Work | HT14: Normal Work | HU14: Normal Work | HV14: Normal Work | HW14: Normal Work | HX14: Normal Work | IA14: Normal Work | IB14: Normal Work | IC14: Normal Work | ID14: Normal Work | IE14: Normal Work | IH14: Normal Work | II14: Normal Work | IJ14: Normal Work | IK14: Normal Work | IL14: Normal Work | IO14: Annual Leave | IP14: Annual Leave | IQ14: Annual Leave | IR14: Annual Leave | IS14: Annual Leave | IV14: Annual Leave | IW14: Annual Leave | IX14: Annual Leave | IY14: Annual Leave | IZ14: Annual Leave | JC14: Normal Work | JD14: Normal Work | JE14: Normal Work | JF14: Normal Work | JG14: Normal Work | JJ14: Normal Work | JK14: Normal Work | JL14: Normal Work | JM14: Normal Work | JN14: Normal Work | JQ14: Normal Work | JR14: Normal Work | JS14: Normal Work | JT14: Normal Work | JU14: Normal Work | JX14: Normal Work | JY14: Normal Work | JZ14: Normal Work | KA14: Normal Work | KB14: Normal Work | KE14: Normal Work | KF14: Normal Work | KG14: SD | KH14: Normal Work | KI14: Normal Work | KL14: Normal Work | KM14: Normal Work | KN14: Normal Work | KO14: Normal Work | KP14: Normal Work | KS14: Normal Work | KT14: Normal Work | KW14: Normal Work | KZ14: Normal Work | LA14: Normal Work
A15: OST
A16: Udit Patel | B16: OST | C16: OST | D16: Normal Work | E16: Normal Work | F16: Normal Work | G16: Normal Work | H16: OST PROJECT | K16: OST PROJECTS | L16: OST PROJECTS | M16: OST PROJECTS | N16: OST PROJECTS | O16: OST PROJECTS | R16: Training | S16: Training | T16: OST Project | U16: OST Project | V16: OST Project | AB16: Project | AC16: Projects | AF16: Project | AG16: Project | AH16: Normal Work | AI16: Normal Work | AJ16: BH | AM16: BH | AN16: OST Project | AT16: Projects | AU16: Projects | AV16: Normal Work | AW16: OST Project | AX16: OST Project | BA16: OST Project | BB16: OST Project | BC16: OST Project | BD16: OST Project | BE16: OST Project | BH16: Projects | BI16: Projects | BJ16: Projects | BK16: Normal Work | BL16: Normal Work | BO16: Normal Work | BP16: Normal Work | BQ16: Normal Work | BR16: Normal Work | BS16: Normal Work | BV16: BH | BW16: Normal Work | BX16: Normal Work | BY16: Normal Work | BZ16: Normal Work | CC16: Normal Work | CD16: Normal Work | CE16: Normal Work | CF16: Normal Work | CG16: Normal Work | CJ16: Service Desk | CK16: Service Desk | CL16: Normal Work | CM16: Normal Work | CN16: Annual Leave | CR16: Service Desk | CS16: Projects | CT16: Service Desk | CU16: Service Desk | CX16: Service Desk | CY16: Service Desk | CZ16: Normal Work | DA16: Normal Work | DB16: Normal Work | DE16: Annual Leave | DF16: Normal Work | DG16: Projects | DH16: Projects | DI16: Annual Leave | DL16: Normal Work | DM16: Normal Work | DN16: Normal Work | DO16: Projects | DP16: Normal Work | DS16: Normal Work | DT16: Normal Work | DU16: Normal Work | DV16: Projects | DW16: Normal Work | DZ16: Normal Work | EA16: Normal Work | EB16: Normal Work | EC16: Normal Work | ED16: Normal Work | EG16: Normal Work | EH16: Normal Work | EI16: Normal Work | EJ16: Normal Work | EK16: Normal Work | EN16: Normal Work | EO16: Normal Work | EP16: Normal Work | EQ16: Normal Work | ER16: Normal Work | EU16: Normal Work | EV16: Normal Work | EW16: Normal Work | EX16: Normal Work | EY16: Normal Work | FB16: Normal Work | FC16: Normal Work | FD16: Normal Work | FE16: Normal Work | FF16: Normal Work | FI16: BAB OST | FJ16: Normal Work | FK16: Normal Work | FL16: Normal Work | FM16: Normal Work | FP16: Normal Work | FQ16: Normal Work | FR16: Normal Work | FS16: Normal Work | FT16: Normal Work | FW16: Normal Work | FX16: Normal Work | FY16: Projects | FZ16: Normal Work | GA16: Normal Work | GE16: Normal Work | GF16: Normal Work | GG16: Normal Work | GH16: Normal Work | GK16: Projects | GL16: Normal Work | GM16: Normal Work | GN16: Normal Work | GO16: Normal Work | GR16: Normal Work | GS16: Normal Work | GT16: Projects | GU16: Normal Work | GV16: Normal Work | GY16: Normal Work | GZ16: Projects | HA16: Normal Work | HB16: Normal Work | HC16: Training | HF16: Normal Work | HG16: Normal Work | HH16: Normal Work | HI16: Normal Work | HJ16: Normal Work | HM16: Normal Work | HN16: Normal Work | HO16: Normal Work | HP16: Normal Work | HQ16: Normal Work | HT16: Normal Work | HU16: Normal Work | HV16: Normal Work | HW16: Normal Work | HX16: Normal Work | IA16: Normal Work | IB16: Normal Work | IC16: Normal Work | ID16: Mitie | IE16: Mitie | IH16: Normal Work | II16: Normal Work | IJ16: Normal Work | IK16: Normal Work | IL16: Normal Work | IO16: Normal Work | IP16: Normal Work | IQ16: Normal Work | IR16: Normal Work | IS16: Normal Work | IV16: Normal Work | IW16: Normal Work | IX16: Normal Work | IY16: Normal Work | IZ16: Normal Work | JC16: Normal Work | JD16: Normal Work | JE16: Normal Work | JF16: Normal Work | JG16: Normal Work | JJ16: Normal Work | JK16: Normal Work | JL16: Normal Work | JM16: Normal Work | JN16: Normal Work | JQ16: Normal Work | JR16: Normal Work | JS16: Normal Work | JT16: Normal Work | JU16: Normal Work | JX16: Normal Work | JY16: Normal Work | JZ16: SD | KA16: Normal Work | KB16: Normal Work | KE16: SD | KF16: GHC IT Audit | KG16: Normal Work | KH16: Normal Work | KI16: Normal Work | KL16: Normal Work | KM16: Normal Work | KN16: Normal Work | KO16: Normal Work | KP16: Normal Work | KS16: GHC IT Audit | KT16: GHC IT Audit | KU16: On-Call | KV16: On-Call | KW16: GHC IT Audit | KX16: On-Call | KY16: On-Call | KZ16: GHC IT Audit | LA16: GHC IT Audit
